<?xml version="1.0" encoding="utf-8"?>
<robot name="abot"
	xmlns:xacro="http://www.ros.org/wiki/xacro">
	<!-- left_wheel -->
	<link name="abot_left_wheel">
		<inertial>
			<origin xyz="1.9255E-10 0.00056576 -1.0414E-10" rpy="0 0 0"/>
			<mass value="0.050464"/>
			<inertia ixx="2.0701E-05" ixy="-3.8089E-14" ixz="1.3584E-15" iyy="3.5827E-05" iyz="2.1838E-15" izz="2.0701E-05"/>
		</inertial>
		<visual>
			<origin xyz="0 0 0" rpy="0 0 0" />
			<geometry>
				<mesh filename="package://abot_description/meshes/abot_left_wheel.STL" />
			</geometry>
			<material name="Green" />
		</visual>
		<collision>
			<origin xyz="0 0 0" rpy="0 0 0" />
			<geometry>
				<mesh filename="package://abot_description/meshes/abot_left_wheel.STL" />
			</geometry>
		</collision>
	</link>
	<!-- left_wheel_geometry -->
	<link name="left_wheel">
		<visual>
			<origin xyz="0 0 0" rpy="${PI/2} 0 0" />
			<geometry>
				<cylinder length="${wheel_width}" radius="${wheel_radius}"/>
			</geometry>
			<material name="Green" />
		</visual>
		<collision>
			<origin xyz="0 0 0" rpy="${PI/2} 0 0" />
			<geometry>
				<cylinder length="${wheel_width}" radius="${wheel_radius}"/>
			</geometry>
		</collision>
	</link>
	<joint name="left_wheel_to_abot_left_wheel" type="fixed">
		<origin xyz="0 0 0" rpy="0 0 0" />
		<parent link="left_wheel" />
		<child link="abot_left_wheel" />
	</joint>
	<joint name="left_wheel_to_base" type="continuous">
		<origin xyz="0 0.068 0.0145" rpy="0 0 0" />
		<parent link="abot_base" />
		<child link="left_wheel" />
		<axis xyz="0 1 0" />
	</joint>
</robot>